Workbook

Sheet Cover
A2: MSME CREDIT APPRAISAL MODEL( NITIN SPINNERS LTD)
A9: Credit Risk Analysis | Altman Z-Score | Financial Ratios | Loan Recommendation
B11: Company Name | D11: NITIN SPINNERS LIMITED
B12: Sector / Industry | D12: Textiles
B13: Data Source | D13: Screener.in — 5 Year Financials
B14: Analysis Period | D14: FY2020 – FY2024
B15: Prepared By | D15: Avantika Pandey
B16: Date | D16: 46157
A18: WORKBOOK NAVIGATION
B19: 1 | C19: Financial Data | E19: Financials pasted from Screener.in here
B20: 2 | C20: Ratio Analysis | E20: Computed liquidity, leverage & profitability ratios
B21: 3 | C21: Altman Z-Score | E21: 5-year Z-Score model with distress zone classification
B22: 4 | C22: Credit Rating | E22: Scorecard → Green / Amber / Red recommendation
B23: 5 | C23: Peer Comparison | E23: Side-by-side analysis of 5 MSME companies
A26: COLOUR LEGEND
B27: Aa | C27: Blue text = Hardcoded input (you enter this)
B28: Aa | C28: Black text = Formula (auto-calculated)
B29: Aa | C29: Green text = Cross-sheet link

Sheet 1_Financial_Data
A1: RAW FINANCIAL DATA OF NITIN SPINNERS — Source: Screener.in
A2: DESCRIPTION : Screener.in → Searched company → Exported to Excel → Pasted P&L, Balance Sheet, Cash Flow data below in ₹ CRORES
A3: Line Item | B3: Source Field (Screener) | C3: FY2020 | D3: FY2021 | E3: FY2022 | F3: FY2023 | G3: FY2024 | H3: Notes
A4: PROFIT & LOSS STATEMENT (₹ crores)
A5: Revenue from Operations | B5: Net Sales / Revenue | C5: ='Raw datasheet'!C5 -> 1622 | D5: ='Raw datasheet'!D5 -> 2690 | E5: ='Raw datasheet'!E5 -> 2404 | F5: ='Raw datasheet'!F5 -> 2902 | G5: ='Raw datasheet'!G5 -> 3300
A6: Expenses | B6: Opex | C6: ='Raw datasheet'!C6 -> 1365 | D6: ='Raw datasheet'!D6 -> 2039 | E6: ='Raw datasheet'!E6 -> 2107 | F6: ='Raw datasheet'!F6 -> 2525 | G6: ='Raw datasheet'!G6 -> 2829
A7: EBITDA | B7: ← revenue – all opex | C7: =C5-C6 -> 257 | D7: =D5-D6 -> 651 | E7: =E5-E6 -> 297 | F7: =F5-F6 -> 377 | G7: =G5-G6 -> 471
A8: Depreciation & Amortisation | B8: Depreciation | C8: ='Raw datasheet'!C11 -> 91 | D8: ='Raw datasheet'!D11 -> 87 | E8: ='Raw datasheet'!E11 -> 87 | F8: ='Raw datasheet'!F11 -> 118 | G8: ='Raw datasheet'!G11 -> 148
A9: EBIT | B9: ← ebitda – Depreciation | C9: =C7-C8 -> 166 | D9: =D7-D8 -> 564 | E9: =E7-E8 -> 210 | F9: =F7-F8 -> 259 | G9: =G7-G8 -> 323
A10: Other Income | B10: Apart from revenue from operations | C10: ='Raw datasheet'!C9 -> 2 | D10: ='Raw datasheet'!D9 -> -3 | E10: ='Raw datasheet'!E9 -> 3 | F10: ='Raw datasheet'!F9 -> 2 | G10: ='Raw datasheet'!G9 -> 4
A11: Finance Costs (Interest) | B11: Interest / Finance Cost | C11: ='Raw datasheet'!C10 -> 62 | D11: ='Raw datasheet'!D10 -> 55 | E11: ='Raw datasheet'!E10 -> 38 | F11: ='Raw datasheet'!F10 -> 83 | G11: ='Raw datasheet'!G10 -> 90
A12: Profit Before Tax (PBT) | B12: PBT | C12: =C9+C10-C11 -> 106 | D12: =D9+D10-D11 -> 506 | E12: =E9+E10-E11 -> 175 | F12: =F9+F10-F11 -> 178 | G12: =G9+G10-G11 -> 237
A13: Tax Expense | B13: Tax | C13: ='Raw datasheet'!C13*'Raw datasheet'!C12 -> 37.45 | D13: ='Raw datasheet'!D13*'Raw datasheet'!D12 -> 182.16 | E13: ='Raw datasheet'!E13*'Raw datasheet'!E12 -> 10.56 | F13: ='Raw datasheet'!F13*'Raw datasheet'!F12 -> 46.28 | G13: ='Raw datasheet'!G13*'Raw datasheet'!G12 -> 61.62
A14: Profit After Tax (PAT) | B14: PAT / Net Profit | C14: =C12-C13 -> 68.55 | D14: =D12-D13 -> 323.84 | E14: =E12-E13 -> 164.44 | F14: =F12-F13 -> 131.72 | G14: =G12-G13 -> 175.38
A16: BALANCE SHEET (₹ crores)
A17: Share Capital | B17: Share Capital | C17: ='Raw datasheet'!C18 -> 56 | D17: ='Raw datasheet'!D18 -> 56 | E17: ='Raw datasheet'!E18 -> 56 | F17: ='Raw datasheet'!F18 -> 56 | G17: ='Raw datasheet'!G18 -> 56
A18: Reserves & Surplus | B18: Reserves | C18: ='Raw datasheet'!C19 -> 507 | D18: ='Raw datasheet'!D19 -> 820 | E18: ='Raw datasheet'!E19 -> 973 | F18: ='Raw datasheet'!F19 -> 1090 | G18: ='Raw datasheet'!G19 -> 1255
A19: Total Equity | B19: ← share capital + reserves | C19: =C17+C18 -> 563 | D19: =D17+D18 -> 876 | E19: =E17+E18 -> 1029 | F19: =F17+F18 -> 1146 | G19: =G17+G18 -> 1311
A20: Long-Term Borrowings | B20: Long Term Debt | C20: ='Raw datasheet'!C21 -> 564 | D20: ='Raw datasheet'!D21 -> 407 | E20: ='Raw datasheet'!E21 -> 561 | F20: ='Raw datasheet'!F21 -> 811 | G20: ='Raw datasheet'!G21 -> 637
A21: Short-Term Borrowings | B21: Short Term Debt / Current portion | C21: ='Raw datasheet'!C22 -> 283 | D21: ='Raw datasheet'!D22 -> 281 | E21: ='Raw datasheet'!E22 -> 419 | F21: ='Raw datasheet'!F22 -> 528 | G21: ='Raw datasheet'!G22 -> 528
A22: Total Debt | B22: ← lt + st borrowings | C22: =C20+C21+'Raw datasheet'!C24 -> 961 | D22: =D20+D21+'Raw datasheet'!D24 -> 688 | E22: =E20+E21+'Raw datasheet'!E24 -> 980 | F22: =F20+F21+'Raw datasheet'!F24 -> 1339 | G22: =G20+G21+'Raw datasheet'!G24 -> 1165
A23: Current Liabilities (Other) | B23: Trade Payables + Other CL | C23: ='Raw datasheet'!C26+'Raw datasheet'!C27+'Raw datasheet'!C28 -> 151 | D23: ='Raw datasheet'!D26+'Raw datasheet'!D27+'Raw datasheet'!D28 -> 260 | E23: ='Raw datasheet'!E26+'Raw datasheet'!E27+'Raw datasheet'!E28 -> 209 | F23: ='Raw datasheet'!F26+'Raw datasheet'!F27+'Raw datasheet'!F28 -> 231 | G23: ='Raw datasheet'!G26+'Raw datasheet'!G27+'Raw datasheet'!G28 -> 256
A24: Total Liabilities | B24: ← equity + total debt + other cl | C24: =C19+C22+C23 -> 1675 | D24: =D19+D22+D23 -> 1824 | E24: =E19+E22+E23 -> 2218 | F24: =F19+F22+F23 -> 2716 | G24: =G19+G22+G23 -> 2732
A25: Fixed Assets (Net Block) | B25: Net Block / PP&E | C25: ='Raw datasheet'!C30 -> 1060 | D25: ='Raw datasheet'!D30 -> 1012 | E25: ='Raw datasheet'!E30 -> 1011 | F25: ='Raw datasheet'!F30 -> 1709 | G25: ='Raw datasheet'!G30 -> 1577
A26: Total Non-Current Assets | B26: Non-Current Assets | C26: ='Raw datasheet'!C30+'Raw datasheet'!C41+'Raw datasheet'!C42+'Raw datasheet'!C37 -> 1062 | D26: ='Raw datasheet'!D30+'Raw datasheet'!D41+'Raw datasheet'!D42+'Raw datasheet'!D37 -> 1012 | E26: ='Raw datasheet'!E30+'Raw datasheet'!E41+'Raw datasheet'!E42+'Raw datasheet'!E37 -> 1351 | F26: ='Raw datasheet'!F30+'Raw datasheet'!F41+'Raw datasheet'!F42+'Raw datasheet'!F37 -> 1711 | G26: ='Raw datasheet'!G30+'Raw datasheet'!G41+'Raw datasheet'!G42+'Raw datasheet'!G37 -> 1584
A27: Cash & Cash Equivalents | B27: Cash & Bank | C27: ='Raw datasheet'!C46 -> 1 | D27: ='Raw datasheet'!D46 -> 1 | E27: ='Raw datasheet'!E46 -> 0 | F27: ='Raw datasheet'!F46 -> 0 | G27: ='Raw datasheet'!G46 -> 10
A28: Trade Receivables (Debtors) | B28: Debtors | C28: ='Raw datasheet'!C45 -> 166 | D28: ='Raw datasheet'!D45 -> 241 | E28: ='Raw datasheet'!E45 -> 223 | F28: ='Raw datasheet'!F45 -> 321 | G28: ='Raw datasheet'!G45 -> 430
A29: Inventories | B29: Inventory | C29: ='Raw datasheet'!C44 -> 355 | D29: ='Raw datasheet'!D44 -> 406 | E29: ='Raw datasheet'!E44 -> 492 | F29: ='Raw datasheet'!F44 -> 564 | G29: ='Raw datasheet'!G44 -> 607
A30: Other Current Assets | B30: Other CA | C30: ='Raw datasheet'!C48+'Raw datasheet'!C47 -> 93 | D30: ='Raw datasheet'!D48+'Raw datasheet'!D47 -> 164 | E30: ='Raw datasheet'!E48+'Raw datasheet'!E47 -> 151 | F30: ='Raw datasheet'!F48+'Raw datasheet'!F47 -> 120 | G30: ='Raw datasheet'!G48+'Raw datasheet'!G47 -> 101
A31: Total Current Assets | B31: ← cash+debtors+inventory+other | C31: =SUM(C27:C30) -> 615 | D31: =SUM(D27:D30) -> 812 | E31: =SUM(E27:E30) -> 866 | F31: =SUM(F27:F30) -> 1005 | G31: =SUM(G27:G30) -> 1148
A32: Total Assets | B32: ← non-current + current assets | C32: =C26+C31 -> 1677 | D32: =D26+D31 -> 1824 | E32: =E26+E31 -> 2217 | F32: =F26+F31 -> 2716 | G32: =G26+G31 -> 2732
A33: Working Capital | B33: ← current assets – Current Liab | C33: =C31-C23 -> 464 | D33: =D31-D23 -> 552 | E33: =E31-E23 -> 657 | F33: =F31-F23 -> 774 | G33: =G31-G23 -> 892
A34: Retained Earnings | B34: Cumulative Reserves (from BS) | C34: ='Raw datasheet'!C19 -> 507 | D34: ='Raw datasheet'!D19 -> 820 | E34: ='Raw datasheet'!E19 -> 973 | F34: ='Raw datasheet'!F19 -> 1090 | G34: ='Raw datasheet'!G19 -> 1255
A35: Market Capitalisation | B35: From Screener / BSE/NSE | C35: 427 | D35: 1582 | E35: 1232 | F35: 1964 | G35: 2692
A37: CASH FLOW STATEMENT (₹ crores)
A38: Cash Flow from Operations (CFO) | B38: CFO | C38: ='Raw datasheet'!C51 -> 155 | D38: ='Raw datasheet'!D51 -> 431 | E38: ='Raw datasheet'!E51 -> 194 | F38: ='Raw datasheet'!F51 -> 163 | G38: ='Raw datasheet'!G51 -> 307
A39: Cash Flow from Investing (CFI) | B39: CFI | C39: ='Raw datasheet'!C52 -> -11 | D39: ='Raw datasheet'!D52 -> -86 | E39: ='Raw datasheet'!E52 -> -433 | F39: ='Raw datasheet'!F52 -> -426 | G39: ='Raw datasheet'!G52 -> -22
A40: Cash Flow from Financing (CFF) | B40: CFF | C40: ='Raw datasheet'!C53 -> -144 | D40: ='Raw datasheet'!D53 -> -345 | E40: ='Raw datasheet'!E53 -> 239 | F40: ='Raw datasheet'!F53 -> 262 | G40: ='Raw datasheet'!G53 -> -279
A41: Net Cash Flow | B41: ← cfo+cfi+cff | C41: =SUM('1_Financial_Data'!C38:C40) -> 0 | D41: =SUM('1_Financial_Data'!D38:D40) -> 0 | E41: =SUM('1_Financial_Data'!E38:E40) -> 0 | F41: =SUM('1_Financial_Data'!F38:F40) -> -1 | G41: =SUM('1_Financial_Data'!G38:G40) -> 6
A42: Annual Debt Repayment | B42: EMI / Principal paid (from CFF notes) | C42: 80.95 | D42: 273.09 | E42: 91.9 | F42: 106.66 | G42: =F22-G22 -> 174
...

Sheet 2_Ratio_Analysis
A1: RATIO ANALYSIS — Formulas pulled from Raw Data sheet
A2: Ratio | B2: Formula | C2: FY2020 | D2: FY2021 | E2: FY2022 | F2: FY2023 | G2: FY2024 | H2: Benchmark | I2: Interpretation
A3: LIQUIDITY RATIOS
A4: Current Ratio | B4: Current Assets / Current Liabilities | C4: =IFERROR('1_Financial_Data'!C31/'1_Financial_Data'!C23,"-") -> 4.0728477 | D4: =IFERROR('1_Financial_Data'!D31/'1_Financial_Data'!D23,"-") -> 3.1230769 | E4: =IFERROR('1_Financial_Data'!E31/'1_Financial_Data'!E23,"-") -> 4.1435407 | F4: =IFERROR('1_Financial_Data'!F31/'1_Financial_Data'!F23,"-") -> 4.3506494 | G4: =IFERROR('1_Financial_Data'!G31/'1_Financial_Data'!G23,"-") -> 4.484375 | H4: > 1.5× | I4: Higher = better short-term liquidity. Below 1× is danger zone.
A5: Quick Ratio | B5: (Current Assets – Inventory) / Current Liabilities | C5: =IFERROR(('1_Financial_Data'!C31-'1_Financial_Data'!C29)/'1_Financial_Data'!C23,"-") -> 1.7218543 | D5: =IFERROR(('1_Financial_Data'!D31-'1_Financial_Data'!D29)/'1_Financial_Data'!D23,"-") -> 1.5615385 | E5: =IFERROR(('1_Financial_Data'!E31-'1_Financial_Data'!E29)/'1_Financial_Data'!E23,"-") -> 1.7894737 | F5: =IFERROR(('1_Financial_Data'!F31-'1_Financial_Data'!F29)/'1_Financial_Data'!F23,"-") -> 1.9090909 | G5: =IFERROR(('1_Financial_Data'!G31-'1_Financial_Data'!G29)/'1_Financial_Data'!G23,"-") -> 2.1132812 | H5: > 1.0× | I5: Excludes inventory. Tests immediate payment ability.
A6: Cash Ratio | B6: Cash / Current Liabilities | C6: =IFERROR('1_Financial_Data'!C27/'1_Financial_Data'!C23,"-") -> 0.0066225166 | D6: =IFERROR('1_Financial_Data'!D27/'1_Financial_Data'!D23,"-") -> 0.0038461538 | E6: =IFERROR('1_Financial_Data'!E27/'1_Financial_Data'!E23,"-") -> 0 | F6: =IFERROR('1_Financial_Data'!F27/'1_Financial_Data'!F23,"-") -> 0 | G6: =IFERROR('1_Financial_Data'!G27/'1_Financial_Data'!G23,"-") -> 0.0390625 | H6: > 0.5× | I6: Most conservative liquidity test.
A7: LEVERAGE / SOLVENCY RATIOS
A8: Debt-to-Equity (D/E) | B8: Total Debt / Total Equity | C8: =IFERROR('1_Financial_Data'!C22/'1_Financial_Data'!C19,"-") -> 1.7069272 | D8: =IFERROR('1_Financial_Data'!D22/'1_Financial_Data'!D19,"-") -> 0.78538813 | E8: =IFERROR('1_Financial_Data'!E22/'1_Financial_Data'!E19,"-") -> 0.95238095 | F8: =IFERROR('1_Financial_Data'!F22/'1_Financial_Data'!F19,"-") -> 1.1684119 | G8: =IFERROR('1_Financial_Data'!G22/'1_Financial_Data'!G19,"-") -> 0.88863463 | H8: < 2.0× | I8: Higher D/E = more leveraged = higher credit risk.
A9: Debt-to-Assets | B9: Total Debt / Total Assets | C9: =IFERROR('1_Financial_Data'!C22/'1_Financial_Data'!C32,"-") -> 0.57304711 | D9: =IFERROR('1_Financial_Data'!D22/'1_Financial_Data'!D32,"-") -> 0.37719298 | E9: =IFERROR('1_Financial_Data'!E22/'1_Financial_Data'!E32,"-") -> 0.44203879 | F9: =IFERROR('1_Financial_Data'!F22/'1_Financial_Data'!F32,"-") -> 0.49300442 | G9: =IFERROR('1_Financial_Data'!G22/'1_Financial_Data'!G32,"-") -> 0.42642753 | H9: < 0.5 | I9: What % of assets are financed by debt.
A10: Interest Coverage Ratio | B10: EBIT / Interest Expense | C10: =IFERROR('1_Financial_Data'!C9/'1_Financial_Data'!C11,"-") -> 2.6774194 | D10: =IFERROR('1_Financial_Data'!D9/'1_Financial_Data'!D11,"-") -> 10.254545 | E10: =IFERROR('1_Financial_Data'!E9/'1_Financial_Data'!E11,"-") -> 5.5263158 | F10: =IFERROR('1_Financial_Data'!F9/'1_Financial_Data'!F11,"-") -> 3.1204819 | G10: =IFERROR('1_Financial_Data'!G9/'1_Financial_Data'!G11,"-") -> 3.5888889 | H10: > 2.5× | I10: Ability to pay interest. Below 1.5× = serious concern.
A11: Total Liabilities to Equity | B11: Total Liabilities / Total Equity | C11: =IFERROR('1_Financial_Data'!C24/'1_Financial_Data'!C19,"-") -> 2.9751332 | D11: =IFERROR('1_Financial_Data'!D24/'1_Financial_Data'!D19,"-") -> 2.0821918 | E11: =IFERROR('1_Financial_Data'!E24/'1_Financial_Data'!E19,"-") -> 2.1554908 | F11: =IFERROR('1_Financial_Data'!F24/'1_Financial_Data'!F19,"-") -> 2.3699825 | G11: =IFERROR('1_Financial_Data'!G24/'1_Financial_Data'!G19,"-") -> 2.0839054 | H11: < 3.0× | I11: Broader leverage check including trade payables.
A12: PROFITABILITY RATIOS
A13: EBITDA Margin | B13: EBITDA / Revenue | C13: =IFERROR('1_Financial_Data'!C7/'1_Financial_Data'!C5,"-") -> 0.15844636 | D13: =IFERROR('1_Financial_Data'!D7/'1_Financial_Data'!D5,"-") -> 0.24200743 | E13: =IFERROR('1_Financial_Data'!E7/'1_Financial_Data'!E5,"-") -> 0.12354409 | F13: =IFERROR('1_Financial_Data'!F7/'1_Financial_Data'!F5,"-") -> 0.12991041 | G13: =IFERROR('1_Financial_Data'!G7/'1_Financial_Data'!G5,"-") -> 0.14272727 | H13: > 15% | I13: Core operating profitability before non-cash items.
A14: EBIT Margin | B14: EBIT / Revenue | C14: =IFERROR('1_Financial_Data'!C9/'1_Financial_Data'!C5,"-") -> 0.10234279 | D14: =IFERROR('1_Financial_Data'!D9/'1_Financial_Data'!D5,"-") -> 0.20966543 | E14: =IFERROR('1_Financial_Data'!E9/'1_Financial_Data'!E5,"-") -> 0.087354409 | F14: =IFERROR('1_Financial_Data'!F9/'1_Financial_Data'!F5,"-") -> 0.089248794 | G14: =IFERROR('1_Financial_Data'!G9/'1_Financial_Data'!G5,"-") -> 0.097878788 | H14: > 10% | I14: Operating profit after depreciation.
A15: PAT Margin (Net Margin) | B15: PAT / Revenue | C15: =IFERROR('1_Financial_Data'!C14/'1_Financial_Data'!C5,"-") -> 0.042262639 | D15: =IFERROR('1_Financial_Data'!D14/'1_Financial_Data'!D5,"-") -> 0.12038662 | E15: =IFERROR('1_Financial_Data'!E14/'1_Financial_Data'!E5,"-") -> 0.068402662 | F15: =IFERROR('1_Financial_Data'!F14/'1_Financial_Data'!F5,"-") -> 0.045389387 | G15: =IFERROR('1_Financial_Data'!G14/'1_Financial_Data'!G5,"-") -> 0.053145455 | H15: > 5% | I15: Bottom-line profitability after all costs & tax.
A16: Return on Equity (ROE) | B16: PAT / Total Equity | C16: =IFERROR('1_Financial_Data'!C14/'1_Financial_Data'!C19,"-") -> 0.12175844 | D16: =IFERROR('1_Financial_Data'!D14/'1_Financial_Data'!D19,"-") -> 0.36968037 | E16: =IFERROR('1_Financial_Data'!E14/'1_Financial_Data'!E19,"-") -> 0.15980564 | F16: =IFERROR('1_Financial_Data'!F14/'1_Financial_Data'!F19,"-") -> 0.11493892 | G16: =IFERROR('1_Financial_Data'!G14/'1_Financial_Data'!G19,"-") -> 0.13377574 | H16: > 12% | I16: Return generated for shareholders.
A17: Return on Assets (ROA) | B17: PAT / Total Assets | C17: =IFERROR('1_Financial_Data'!C14/'1_Financial_Data'!C32,"-") -> 0.040876565 | D17: =IFERROR('1_Financial_Data'!D14/'1_Financial_Data'!D32,"-") -> 0.17754386 | E17: =IFERROR('1_Financial_Data'!E14/'1_Financial_Data'!E32,"-") -> 0.074172305 | F17: =IFERROR('1_Financial_Data'!F14/'1_Financial_Data'!F32,"-") -> 0.048497791 | G17: =IFERROR('1_Financial_Data'!G14/'1_Financial_Data'!G32,"-") -> 0.064194729 | H17: > 5% | I17: Efficiency of asset utilisation.
A18: DEBT SERVICEABILITY RATIOS
A19: DSCR | B19: CFO / (Interest + Debt Repayment) | C19: =IFERROR('1_Financial_Data'!C7/('1_Financial_Data'!C43+'1_Financial_Data'!C42),"-") -> 1.8028762 | D19: =IFERROR('1_Financial_Data'!D7/('1_Financial_Data'!D43+'1_Financial_Data'!D42),"-") -> 1.9821575 | E19: =IFERROR('1_Financial_Data'!E7/('1_Financial_Data'!E43+'1_Financial_Data'!E42),"-") -> 2.2920204 | F19: =IFERROR('1_Financial_Data'!F7/('1_Financial_Data'!F43+'1_Financial_Data'!F42),"-") -> 1.9846283 | G19: =IFERROR('1_Financial_Data'!G7/('1_Financial_Data'!G43+'1_Financial_Data'!G42),"-") -> 1.7815266 | H19: > 1.25× | I19: KEY RATIO for lenders. Below 1.0× = cannot service debt from operations.
A20: CFO to Total Debt | B20: CFO / Total Debt | C20: =IFERROR('1_Financial_Data'!C38/'1_Financial_Data'!C22,"-") -> 0.16129032 | D20: =IFERROR('1_Financial_Data'!D38/'1_Financial_Data'!D22,"-") -> 0.62645349 | E20: =IFERROR('1_Financial_Data'!E38/'1_Financial_Data'!E22,"-") -> 0.19795918 | F20: =IFERROR('1_Financial_Data'!F38/'1_Financial_Data'!F22,"-") -> 0.12173264 | G20: =IFERROR('1_Financial_Data'!G38/'1_Financial_Data'!G22,"-") -> 0.26351931 | H20: > 0.2 | I20: How fast can the company repay debt from operations.
A21: EFFICIENCY / ACTIVITY RATIOS
A22: Debtor Days | B22: (Trade Receivables / Revenue) × 365 | C22: =IFERROR(('1_Financial_Data'!C28/'1_Financial_Data'!C5)*365,"-") -> 37.355117 | D22: =IFERROR(('1_Financial_Data'!D28/'1_Financial_Data'!D5)*365,"-") -> 32.700743 | E22: =IFERROR(('1_Financial_Data'!E28/'1_Financial_Data'!E5)*365,"-") -> 33.858153 | F22: =IFERROR(('1_Financial_Data'!F28/'1_Financial_Data'!F5)*365,"-") -> 40.37388 | G22: =IFERROR(('1_Financial_Data'!G28/'1_Financial_Data'!G5)*365,"-") -> 47.560606 | H22: < 60 days | I22: How long to collect from customers. Lower = better.
A23: Inventory Days | B23: (Inventory / Revenue) × 365 | C23: =IFERROR(('1_Financial_Data'!C29/'1_Financial_Data'!C5)*365,"-") -> 79.885943 | D23: =IFERROR(('1_Financial_Data'!D29/'1_Financial_Data'!D5)*365,"-") -> 55.089219 | E23: =IFERROR(('1_Financial_Data'!E29/'1_Financial_Data'!E5)*365,"-") -> 74.700499 | F23: =IFERROR(('1_Financial_Data'!F29/'1_Financial_Data'!F5)*365,"-") -> 70.937285 | G23: =IFERROR(('1_Financial_Data'!G29/'1_Financial_Data'!G5)*365,"-") -> 67.137879 | H23: < 90 days | I23: How fast inventory is sold. Lower = better.
A24: Asset Turnover | B24: Revenue / Total Assets | C24: =IFERROR('1_Financial_Data'!C5/'1_Financial_Data'!C32,"-") -> 0.96720334 | D24: =IFERROR('1_Financial_Data'!D5/'1_Financial_Data'!D32,"-") -> 1.4747807 | E24: =IFERROR('1_Financial_Data'!E5/'1_Financial_Data'!E32,"-") -> 1.0843482 | F24: =IFERROR('1_Financial_Data'!F5/'1_Financial_Data'!F32,"-") -> 1.0684831 | G24: =IFERROR('1_Financial_Data'!G5/'1_Financial_Data'!G32,"-") -> 1.2079063 | H24: > 0.8× | I24: Revenue generated per rupee of assets.
A25: GROWTH METRICS
A26: Revenue Growth YoY | B26: (Revenue_t / Revenue_t-1) – 1 | C26: N/A | D26: =IFERROR(('1_Financial_Data'!D5/'1_Financial_Data'!C5)-1,"-") -> 0.65844636 | E26: =IFERROR(('1_Financial_Data'!E5/'1_Financial_Data'!D5)-1,"-") -> -0.1063197 | F26: =IFERROR(('1_Financial_Data'!F5/'1_Financial_Data'!E5)-1,"-") -> 0.20715474 | G26: =IFERROR(('1_Financial_Data'!G5/'1_Financial_Data'!F5)-1,"-") -> 0.1371468 | H26: > 10% p.a. | I26: Consistent growth signals business health.
A27: PAT Growth YoY | B27: (PAT_t / PAT_t-1) – 1 | C27: N/A | D27: =IFERROR(('1_Financial_Data'!D14/'1_Financial_Data'!C14)-1,"-") -> 3.724143 | E27: =IFERROR(('1_Financial_Data'!E14/'1_Financial_Data'!D14)-1,"-") -> -0.49221838 | F27: =IFERROR(('1_Financial_Data'!F14/'1_Financial_Data'!E14)-1,"-") -> -0.19897835 | G27: =IFERROR(('1_Financial_Data'!G14/'1_Financial_Data'!F14)-1,"-") -> 0.33146067 | H27: > 10% p.a. | I27: Earnings growth shows improving profitability.

Sheet 3_Altman_ZScore
A1: ALTMAN Z-SCORE MODEL — Bankruptcy Prediction & Default Risk
A2: Formula: Z = 1.2×X1 + 1.4×X2 + 3.3×X3 + 0.6×X4 + 1.0×X5 | Safe Zone: Z > 2.99 | Grey Zone: 1.81–2.99 | Distress Zone: Z < 1.81
A3: Variable | B3: Component | C3: Formula | D3: Weight | E3: FY2020 | F3: FY2021 | G3: FY2022 | H3: FY2023 | I3: FY2024
A4: STEP 1 — COMPUTE THE FIVE VARIABLES (Raw Ratios)
A5: X1 | B5: Working Capital / Total Assets | C5: Liquidity of assets | D5: 1.2 | E5: =IFERROR('1_Financial_Data'!C33/'1_Financial_Data'!C32,"-") -> 0.27668456 | F5: =IFERROR('1_Financial_Data'!D33/'1_Financial_Data'!D32,"-") -> 0.30263158 | G5: =IFERROR('1_Financial_Data'!E33/'1_Financial_Data'!E32,"-") -> 0.29634641 | H5: =IFERROR('1_Financial_Data'!F33/'1_Financial_Data'!F32,"-") -> 0.28497791 | I5: =IFERROR('1_Financial_Data'!G33/'1_Financial_Data'!G32,"-") -> 0.32650073
A6: X2 | B6: Retained Earnings / Total Assets | C6: Cumulative profitability | D6: 1.4 | E6: =IFERROR('1_Financial_Data'!C18/'1_Financial_Data'!C32,"-") -> 0.30232558 | F6: =IFERROR('1_Financial_Data'!D18/'1_Financial_Data'!D32,"-") -> 0.4495614 | G6: =IFERROR('1_Financial_Data'!E18/'1_Financial_Data'!E32,"-") -> 0.43888137 | H6: =IFERROR('1_Financial_Data'!F18/'1_Financial_Data'!F32,"-") -> 0.40132548 | I6: =IFERROR('1_Financial_Data'!G18/'1_Financial_Data'!G32,"-") -> 0.45937042
A7: X3 | B7: EBIT / Total Assets | C7: Operating efficiency | D7: 3.3 | E7: =IFERROR('1_Financial_Data'!C9/'1_Financial_Data'!C32,"-") -> 0.098986285 | F7: =IFERROR('1_Financial_Data'!D9/'1_Financial_Data'!D32,"-") -> 0.30921053 | G7: =IFERROR('1_Financial_Data'!E9/'1_Financial_Data'!E32,"-") -> 0.094722598 | H7: =IFERROR('1_Financial_Data'!F9/'1_Financial_Data'!F32,"-") -> 0.095360825 | I7: =IFERROR('1_Financial_Data'!G9/'1_Financial_Data'!G32,"-") -> 0.1182284
A8: X4 | B8: Market Capitalisation / Total Liabilities | C8: Market-based solvency | D8: 0.6 | E8: =IFERROR('1_Financial_Data'!C35/'1_Financial_Data'!C24,"-") -> 0.25492537 | F8: =IFERROR('1_Financial_Data'!D35/'1_Financial_Data'!D24,"-") -> 0.86732456 | G8: =IFERROR('1_Financial_Data'!E35/'1_Financial_Data'!E24,"-") -> 0.55545537 | H8: =IFERROR('1_Financial_Data'!F35/'1_Financial_Data'!F24,"-") -> 0.72312224 | I8: =IFERROR('1_Financial_Data'!G35/'1_Financial_Data'!G24,"-") -> 0.98535871
A9: X5 | B9: Revenue / Total Assets | C9: Asset utilisation | D9: 1 | E9: =IFERROR('1_Financial_Data'!C5/'1_Financial_Data'!C32,"-") -> 0.96720334 | F9: =IFERROR('1_Financial_Data'!D5/'1_Financial_Data'!D32,"-") -> 1.4747807 | G9: =IFERROR('1_Financial_Data'!E5/'1_Financial_Data'!E32,"-") -> 1.0843482 | H9: =IFERROR('1_Financial_Data'!F5/'1_Financial_Data'!F32,"-") -> 1.0684831 | I9: =IFERROR('1_Financial_Data'!G5/'1_Financial_Data'!G32,"-") -> 1.2079063
A11: STEP 2 — WEIGHTED COMPONENTS (Weight × Variable)
A12: 1.2×X1 | B12: 1.2 × X1 | C12: Weight × X1 value | D12: 1.2 | E12: =IFERROR(D12*E5,"-") -> 0.33202147 | F12: =IFERROR(D12*F5,"-") -> 0.36315789 | G12: =IFERROR(D12*G5,"-") -> 0.3556157 | H12: =IFERROR(D12*H5,"-") -> 0.34197349 | I12: =IFERROR(D12*I5,"-") -> 0.39180088
A13: 1.4×X2 | B13: 1.4 × X2 | C13: Weight × X2 value | D13: 1.4 | E13: =IFERROR(D13*E6,"-") -> 0.42325581 | F13: =IFERROR(D13*F6,"-") -> 0.62938596 | G13: =IFERROR(D13*G6,"-") -> 0.61443392 | H13: =IFERROR(D13*H6,"-") -> 0.56185567 | I13: =IFERROR(D13*I6,"-") -> 0.64311859
A14: 3.3×X3 | B14: 3.3 × X3 | C14: Weight × X3 value | D14: 3.3 | E14: =IFERROR(D14*E7,"-") -> 0.32665474 | F14: =IFERROR(D14*F7,"-") -> 1.0203947 | G14: =IFERROR(D14*G7,"-") -> 0.31258457 | H14: =IFERROR(D14*H7,"-") -> 0.31469072 | I14: =IFERROR(D14*I7,"-") -> 0.39015373
A15: 0.6×X4 | B15: 0.6 × X4 | C15: Weight × X4 value | D15: 0.6 | E15: =IFERROR(D15*E8,"-") -> 0.15295522 | F15: =IFERROR(D15*F8,"-") -> 0.52039474 | G15: =IFERROR(D15*G8,"-") -> 0.33327322 | H15: =IFERROR(D15*H8,"-") -> 0.43387334 | I15: =IFERROR(D15*I8,"-") -> 0.59121523
A16: 1.0×X5 | B16: 1.0 × X5 | C16: Weight × X5 value | D16: 1 | E16: =IFERROR(D16*E9,"-") -> 0.96720334 | F16: =IFERROR(D16*F9,"-") -> 1.4747807 | G16: =IFERROR(D16*G9,"-") -> 1.0843482 | H16: =IFERROR(D16*H9,"-") -> 1.0684831 | I16: =IFERROR(D16*I9,"-") -> 1.2079063
A18: STEP 3 — ALTMAN Z-SCORE & RISK ZONE CLASSIFICATION
A19: Z-Score | B19: Z-Score for all five years | E19: =IFERROR(E12+E13+E14+E15+E16,"-") -> 2.2020906 | F19: =IFERROR(F12+F13+F14+F15+F16,"-") -> 4.008114 | G19: =IFERROR(G12+G13+G14+G15+G16,"-") -> 2.7002556 | H19: =IFERROR(H12+H13+H14+H15+H16,"-") -> 2.7208763 | I19: =IFERROR(I12+I13+I14+I15+I16,"-") -> 3.2241947
A20: Risk Zone | B20: IF Z>2.99 → "✅ Safe Zone" | 1.81–2.99 → "⚠ Grey Zone" | <1.81 → "🔴 Distress" | E20: =IFERROR(IF(E19>2.99,"✅ Safe Zone",IF(E19>=1.81,"⚠ Grey Zone","🔴 Distress")),"-") -> ⚠ Grey Zone | F20: =IFERROR(IF(F19>2.99,"✅ Safe Zone",IF(F19>=1.81,"⚠ Grey Zone","🔴 Distress")),"-") -> ✅ Safe Zone | G20: =IFERROR(IF(G19>2.99,"✅ Safe Zone",IF(G19>=1.81,"⚠ Grey Zone","🔴 Distress")),"-") -> ⚠ Grey Zone | H20: =IFERROR(IF(H19>2.99,"✅ Safe Zone",IF(H19>=1.81,"⚠ Grey Zone","🔴 Distress")),"-") -> ⚠ Grey Zone | I20: =IFERROR(IF(I19>2.99,"✅ Safe Zone",IF(I19>=1.81,"⚠ Grey Zone","🔴 Distress")),"-") -> ✅ Safe Zone
A22: ZONE THRESHOLDS & INTERPRETATION
A23: Above 2.99 | B23: ✅ SAFE ZONE | C23: Company is financially healthy. Low probability of default. Suitable for credit.
A24: 1.81 – 2.99 | B24: ⚠ GREY ZONE | C24: Caution warranted. Requires deeper analysis. Add monitoring covenants if lending.
A25: Below 1.81 | B25: 🔴 DISTRESS ZONE | C25: High bankruptcy risk. Decline or seek strong collateral. Review trend direction.

Sheet 4_Credit_Rating
A1: CREDIT RATING SCORECARD — Final Loan Recommendation
A2: DESCRIPTION: For each criterion, entered a score 1-5 in the yellow Score column for the LATEST YEAR (FY2024) based on the benchmarks. The model totals the score and maps it to a Green / Amber / Red credit recommendation.
A3: Criterion | B3: Weight (%) | C3: Score (1-5) | D3: Weighted Score | E3: Benchmark Reference | F3: Score Guide
A4: QUANTITATIVE CRITERIA (70% weight)
A5: DSCR (FY2024) | B5: 0.15 | C5: 4 | D5: =IFERROR(B5*C5,"-") -> 0.6 | E5: Pull from Ratio Analysis sheet | F5: 5: >2.0 | 4: 1.5-2.0 | 3: 1.25-1.5 | 2: 1.0-1.25 | 1: <1.0
A6: Current Ratio | B6: 0.1 | C6: 5 | D6: =IFERROR(B6*C6,"-") -> 0.5 | E6: Pull from Ratio Analysis sheet | F6: 5: >2.0 | 4: 1.5-2.0 | 3: 1.25-1.5 | 2: 1.0-1.25 | 1: <1.0
A7: Debt-to-Equity | B7: 0.1 | C7: 4 | D7: =IFERROR(B7*C7,"-") -> 0.4 | E7: Pull from Ratio Analysis sheet | F7: 5: <0.5 | 4: 0.5-1.0 | 3: 1.0-2.0 | 2: 2.0-3.0 | 1: >3.0
A8: EBITDA Margin | B8: 0.1 | C8: 3 | D8: =IFERROR(B8*C8,"-") -> 0.3 | E8: Pull from Ratio Analysis sheet | F8: 5: >25% | 4: 15-25% | 3: 10-15% | 2: 5-10% | 1: <5%
A9: Revenue Growth (3yr avg) | B9: 0.1 | C9: 3 | D9: =IFERROR(B9*C9,"-") -> 0.3 | E9: Average of FY22-24 growth | F9: 5: >20% | 4: 10-20% | 3: 5-10% | 2: 0-5% | 1: Negative
A10: Altman Z-Score | B10: 0.1 | C10: 4 | D10: =IFERROR(B10*C10,"-") -> 0.4 | E10: Pull from Z-Score sheet | F10: 5: >3.5 | 4: 2.99-3.5 | 3: 1.81-2.99 | 2: 1.0-1.81 | 1: <1.0
A11: Interest Coverage | B11: 0.05 | C11: 4 | D11: =IFERROR(B11*C11,"-") -> 0.2 | E11: Pull from Ratio Analysis sheet | F11: 5: >5.0 | 4: 3.0-5.0 | 3: 2.0-3.0 | 2: 1.5-2.0 | 1: <1.5
A13: QUALITATIVE CRITERIA (30% weight)
A14: Management Quality & Track Record | B14: 0.1 | C14: 4 | D14: =IFERROR(B14*C14,"-") -> 0.4 | E14: Industry experience, promoter background, governance | F14: 5: Excellent | 4: Good | 3: Average | 2: Below avg | 1: Concerns
A15: Industry Outlook | B15: 0.1 | C15: 4 | D15: =IFERROR(B15*C15,"-") -> 0.4 | E15: Sector growth, regulatory environment, competition | F15: 5: Very positive | 4: Positive | 3: Stable | 2: Uncertain | 1: Declining
A16: Collateral / Security Coverage | B16: 0.05 | C16: 3 | D16: =IFERROR(B16*C16,"-") -> 0.15 | E16: Asset coverage ratio, quality of collateral | F16: 5: >2.0× | 4: 1.5-2.0× | 3: 1.0-1.5× | 2: <1.0× | 1: No collateral
A17: Business Model Sustainability | B17: 0.05 | C17: 4 | D17: =IFERROR(B17*C17,"-") -> 0.2 | E17: Customer diversification, product moat, repeat revenue | F17: 5: Very stable | 4: Stable | 3: Moderate risk | 2: High risk | 1: Unsustainable
A19: FINAL SCORE & CREDIT DECISION
A20: TOTAL WEIGHTED SCORE | D20: =IFERROR(D5+D6+D7+D8+D9+D10+D11+D14+D15+D16+D17,"-") -> 3.85 | E20: Out of 5.00 maximum
A21: CREDIT RECOMMENDATION | D21: =IFERROR(IF(D20>=3.5,"✅ GREEN — Approve Loan",IF(D20>=2.5,"⚠ AMBER — Conditional Approval","🔴 RED — Decline / High Risk")),"-") -> ✅ GREEN — Approve Loan
A23: RATING SCALE REFERENCE
A24: 3.5 – 5.0 | B24: ✅ GREEN | C24: Approve. Strong financials. Standard terms.
A25: 2.5 – 3.49 | B25: ⚠ AMBER | C25: Conditional. Add covenants, enhanced monitoring, or collateral.
A26: 0 – 2.49 | B26: 🔴 RED | C26: Decline or refer to senior credit committee with mitigation plan.

Sheet 5_Peer_Comparison
A1: PEER COMPARISON — 5 MSMEs, Same Sector, Latest Year (FY2024)
A2: DESCRIPTION: Entered company names in Row 3 (columns B–F). Filled each company's FY2024 ratio values below in BLUE. Formulas auto-rank and flag best performer.
A3: Metric | B3: Sportking India Ltd | C3: Sangam (India) Ltd | D3: Pashupati Cotspin | E3: Sutlej Textiles and Industries | F3: Deepak Spinners | G3: Best in Peer
A4: Revenue (₹ Lakhs) | B4: 2524 | C4: 2843 | D4: 637 | E4: 2677 | F4: 524 | G4: =IFERROR(MIN(B4:F4),"-") -> 524
A5: Revenue Growth YoY (%)(last years avg) | B5: 0.062 | C5: 0.0737 | D5: 0.12 | E5: 0.0276 | F5: 0.1124 | G5: =IFERROR(MAX(B5:F5),"-") -> 0.12
A6: EBITDA Margin (%) | B6: 0.1147 | C6: 0.08 | D6: 0.0619 | E6: 0.02 | F6: 0.014 | G6: =IFERROR(MAX(B6:F6),"-") -> 0.1147
A7: PBT Margin (%) | B7: 0.0593 | C7: 0.0136 | D7: 0.0265 | E7: 0.041 | F7: 0.0266 | G7: =IFERROR(MAX(B7:F7),"-") -> 0.0593
A8: Current Ratio | B8: 2.63 | C8: 1.2 | D8: 1.57 | E8: 1.22 | F8: 1.54 | G8: =IFERROR(MAX(B8:F8),"-") -> 2.63
A9: Debt-to-Equity | B9: 0.58 | C9: 1.13 | D9: 0.73 | E9: 0.98 | F9: 0.16 | G9: =IFERROR(MIN(B9:F9),"-") -> 0.16
A10: Interest Coverage | B10: =204/54 -> 3.7777778 | C10: 2.75 | D10: 2.95 | E10: 1.02 | F10: =-10/3.76 -> -2.6595745 | G10: =IFERROR(MAX(B10:F10),"-") -> 3.7777778
A11: DSCR | B11: 0.87 | C11: =5084/(9468+9716) -> 0.26501251 | D11: =25/(37.37+13.41) -> 0.49231981 | E11: =(-47+111.21)/211 -> 0.3043128 | F11: =5/212 -> 0.023584906 | G11: =IFERROR(MAX(B11:F11),"-") -> 0.87
A12: ROE (%) | B12: 0.1086 | C12: 0.0315 | D12: 0.0834 | E12: 0.0764 | F12: 0.0452 | G12: =IFERROR(MAX(B12:F12),"-") -> 0.1086
A13: Altman Z-Score | B13: =C37 -> 3.4440563 | C13: =D37 -> 2.0811613 | D13: =E37 -> 3.6113378 | E13: =F37 -> 2.1755631 | F13: =G37 -> 5.4072072 | G13: =IFERROR(MAX(B13:F13),"-") -> 5.4072072
A14: Weighted Composite Score | B14: =IFERROR((RANK(B13,$B$13:$F$13,0)*0.4)+(RANK(B11,$B$11:$F$11,0)*0.3)+(RANK(B6,$B$6:$F$6,0)*0.3),"") -> 1.8 | C14: =IFERROR((RANK(C13,$B$13:$F$13,0)*0.4)+(RANK(C11,$B$11:$F$11,0)*0.3)+(RANK(C6,$B$6:$F$6,0)*0.3),"") -> 3.8 | D14: =IFERROR((RANK(D13,$B$13:$F$13,0)*0.4)+(RANK(D11,$B$11:$F$11,0)*0.3)+(RANK(D6,$B$6:$F$6,0)*0.3),"") -> 2.3 | E14: =IFERROR((RANK(E13,$B$13:$F$13,0)*0.4)+(RANK(E11,$B$11:$F$11,0)*0.3)+(RANK(E6,$B$6:$F$6,0)*0.3),"") -> 3.7 | F14: =IFERROR((RANK(F13,$B$13:$F$13,0)*0.4)+(RANK(F11,$B$11:$F$11,0)*0.3)+(RANK(F6,$B$6:$F$6,0)*0.3),"") -> 3.4 | G14: =IFERROR((RANK(G13,$B$13:$F$13,0)*0.4)+(RANK(G11,$B$11:$F$11,0)*0.3)+(RANK(G6,$B$6:$F$6,0)*0.3),"") -> 1
A15: OVERALL PEER RANK (Based on Altman Z-Score + DSCR + EBITDA Margin)
A16: Composite Rank | B16: =IFERROR(RANK(B14,$B$14:$F$14,1),"") -> 1 | C16: =IFERROR(RANK(C14,$B$14:$F$14,1),"") -> 5 | D16: =IFERROR(RANK(D14,$B$14:$F$14,1),"") -> 2 | E16: =IFERROR(RANK(E14,$B$14:$F$14,1),"") -> 4 | F16: =IFERROR(RANK(F14,$B$14:$F$14,1),"") -> 3
A19: PEER ALTMAN Z-SCORE CALCULATOR — FY2024 Snapshot (All 5 Companies)
A20: Enter FY2024 values (₹ Lakhs) in the YELLOW cells below. Z-Score and Risk Zone auto-calculate. These feed into the Peer Comparison table above.
A21: Input / Variable | B21: Formula | C21: Sportking India Ltd | D21: Sangam (India) Ltd | E21: Pashupati Cotspin | F21: Sutlej Textiles and Industries | G21: Deepak Spinners
A22: STEP 1 — RAW INPUTS (Paste from Screener FY2024 data, ₹ Lakhs)
A23: Working Capital | B23: Current Assets – Current Liabilities | C23: =984-374 -> 610 | D23: =1385.7-1159.4 -> 226.3 | E23: 58.85 | F23: =988.79-809.35 -> 179.44 | G23: =149-107 -> 42
A24: Total Assets | B24: Balance Sheet total | C24: 1775 | D24: =2955.25 -> 2955.25 | E24: 299 | F24: 2051.24 | G24: 333
A25: Retained Earnings | B25: Cumulative Reserves (from BS) | C25: 993 | D25: =956.53 -> 956.53 | E25: 138.55 | F25: 878.41 | G25: 218
A26: EBIT | B26: Revenue – OpEx – Depreciation | C26: 204 | D26: =131 -> 131 | E26: 30 | F26: =-47 -> -47 | G26: -10
A27: Total Liabilities | B27: Equity + Debt + Other Liabilities | C27: 1775 | D27: =2955.25 -> 2955.25 | E27: 299 | F27: 2051.24 | G27: 333
A28: Revenue | B28: Net Sales / Revenue from Operations | C28: 2524 | D28: =2856.95 -> 2856.95 | E28: =637 -> 637 | F28: 2677 | G28: 524
A29: Market Capitalisation | B29: From Screener / BSE market cap | C29: 1323 | D29: 2084 | E29: 132 | F29: 826 | G29: 1590
A30: STEP 2 — FIVE VARIABLES (Auto-calculated)
A31: X1 (1.2×) | B31: Working Capital / Total Assets | C31: =IFERROR(C23/C24,"-") -> 0.34366197 | D31: =IFERROR(D23/D24,"-") -> 0.076575586 | E31: =IFERROR(E23/E24,"-") -> 0.19682274 | F31: =IFERROR(F23/F24,"-") -> 0.087478793 | G31: =IFERROR(G23/G24,"-") -> 0.12612613
A32: X2 (1.4×) | B32: Retained Earnings / Total Assets | C32: =IFERROR(C25/C24,"-") -> 0.55943662 | D32: =IFERROR(D25/D24,"-") -> 0.32367143 | E32: =IFERROR(E25/E24,"-") -> 0.46337793 | F32: =IFERROR(F25/F24,"-") -> 0.42823365 | G32: =IFERROR(G25/G24,"-") -> 0.65465465
A33: X3 (3.3×) | B33: EBIT / Total Assets | C33: =IFERROR(C26/C24,"-") -> 0.11492958 | D33: =IFERROR(D26/D24,"-") -> 0.044327891 | E33: =IFERROR(E26/E24,"-") -> 0.10033445 | F33: =IFERROR(F26/F24,"-") -> -0.02291297 | G33: =IFERROR(G26/G24,"-") -> -0.03003003
A34: X4 (0.6×) | B34: Market Cap / Total Liabilities | C34: =IFERROR(C29/C27,"-") -> 0.74535211 | D34: =IFERROR(D29/D27,"-") -> 0.70518569 | E34: =IFERROR(E29/E27,"-") -> 0.44147157 | F34: =IFERROR(F29/F27,"-") -> 0.40268326 | G34: =IFERROR(G29/G27,"-") -> 4.7747748
A35: X5 (1.0×) | B35: Revenue / Total Assets | C35: =IFERROR(C28/C24,"-") -> 1.4219718 | D35: =IFERROR(D28/D24,"-") -> 0.96673716 | E35: =IFERROR(E28/E24,"-") -> 2.1304348 | F35: =IFERROR(F28/F24,"-") -> 1.3050643 | G35: =IFERROR(G28/G24,"-") -> 1.5735736
A36: STEP 3 — ALTMAN Z-SCORE & RISK ZONE
A37: Altman Z-Score | B37: 1.2×X1 + 1.4×X2 + 3.3×X3 + 0.6×X4 + 1.0×X5 | C37: =IFERROR(1.2*C31+1.4*C32+3.3*C33+0.6*C34+1*C35,"-") -> 3.4440563 | D37: =IFERROR(1.2*D31+1.4*D32+3.3*D33+0.6*D34+1*D35,"-") -> 2.0811613 | E37: =IFERROR(1.2*E31+1.4*E32+3.3*E33+0.6*E34+1*E35,"-") -> 3.6113378 | F37: =IFERROR(1.2*F31+1.4*F32+3.3*F33+0.6*F34+1*F35,"-") -> 2.1755631 | G37: =IFERROR(1.2*G31+1.4*G32+3.3*G33+0.6*G34+1*G35,"-") -> 5.4072072
A38: Risk Zone | B38: >2.99 Safe | 1.81–2.99 Grey | <1.81 Distress | C38: =IFERROR(IF(C37>2.99,"✅ Safe",IF(C37>=1.81,"⚠ Grey","🔴 Distress")),"-") -> ✅ Safe | D38: =IFERROR(IF(D37>2.99,"✅ Safe",IF(D37>=1.81,"⚠ Grey","🔴 Distress")),"-") -> ⚠ Grey | E38: =IFERROR(IF(E37>2.99,"✅ Safe",IF(E37>=1.81,"⚠ Grey","🔴 Distress")),"-") -> ✅ Safe | F38: =IFERROR(IF(F37>2.99,"✅ Safe",IF(F37>=1.81,"⚠ Grey","🔴 Distress")),"-") -> ⚠ Grey | G38: =IFERROR(IF(G37>2.99,"✅ Safe",IF(G37>=1.81,"⚠ Grey","🔴 Distress")),"-") -> ✅ Safe
A40: ZONE REFERENCE
A41: Above 2.99 | B41: ✅ SAFE ZONE | C41: Low default risk — suitable for lending
A42: 1.81–2.99 | B42: ⚠ GREY ZONE | C42: Monitor closely — add covenants if lending
A43: Below 1.81 | B43: 🔴 DISTRESS | C43: High default risk — decline or seek collateral

Sheet Raw datasheet
B2: Raw Financial Data of Nitin Spinners Ltd.(All figures in ₹ crores)
B3: Line Item | C3: FY2020 | D3: FY2021 | E3: FY2022 | F3: FY2023 | G3: FY2024
B4: Profit and Loss Statement
B5: Sales | C5: 1622 | D5: 2690 | E5: 2404 | F5: 2902 | G5: 3300
B6: Expenses (Opex) | C6: 1365 | D6: 2039 | E6: 2107 | F6: 2525 | G6: 2829
B7: Operating Profit | C7: 257 | D7: 652 | E7: 297 | F7: 377 | G7: 471
B8: OPM % | C8: 0.16 | D8: 0.24 | E8: 0.12 | F8: 0.13 | G8: 0.14
B9: Other Income | C9: 2 | D9: -3 | E9: 3 | F9: 2 | G9: 4
B10: Interest | C10: 62 | D10: 55 | E10: 38 | F10: 83 | G10: 90
B11: Depreciation | C11: 91 | D11: 87 | E11: 87 | F11: 118 | G11: 148
B12: Profit before tax | C12: 107 | D12: 506 | E12: 176 | F12: 178 | G12: 237
B13: Tax % | C13: 0.35 | D13: 0.36 | E13: 0.06 | F13: 0.26 | G13: 0.26
B14: Net Profit | C14: 69 | D14: 326 | E14: 165 | F14: 132 | G14: 175
B15: EPS in Rs | C15: 12.25 | D15: 58.01 | E15: 29.32 | F15: 23.39 | G15: 31.2
B16: Dividend Payout % | C16: 0.12 | D16: 0.04 | E16: 0.09 | F16: 0.11 | G16: 0.1
B17: Balance Sheet
B18: Equity Capital | C18: 56 | D18: 56 | E18: 56 | F18: 56 | G18: 56
B19: Reserves | C19: 507 | D19: 820 | E19: 973 | F19: 1090 | G19: 1255
B20: Borrowings - | C20: 962 | D20: 689 | E20: 980 | F20: 1339 | G20: 1165
B21: Long term Borrowings | C21: 564 | D21: 407 | E21: 561 | F21: 811 | G21: 637
B22: Short term Borrowings | C22: 283 | D22: 281 | E22: 419 | F22: 528 | G22: 528
B23: Lease Liabilities | C23: 0 | D23: 0 | E23: 0 | F23: 0 | G23: 0
B24: Other Borrowings | C24: 114 | D24: 0 | E24: 0 | F24: 0 | G24: 0
B25: Other Liabilities - | C25: 151 | D25: 260 | E25: 209 | F25: 231 | G25: 256
B26: Trade Payables | C26: 55 | D26: 82 | E26: 52 | F26: 74 | G26: 89
B27: Advance from Customers | C27: 4 | D27: 14 | E27: 5 | F27: 4 | G27: 2
B28: Other liability items | C28: 92 | D28: 164 | E28: 152 | F28: 153 | G28: 165
B29: Total Liabilities | C29: 1676 | D29: 1824 | E29: 2218 | F29: 2717 | G29: 2732
... B49: Total Assets | C49: 1676 | D49: 1824 | E49: 2218 | F49: 2717 | G49: 2732
B50: Cash Flow Statement
B51: Cash from Operating Activity | C51: 155 | D51: 431 | E51: 194 | F51: 163 | G51: 307
B52: Cash from Investing Activity | C52: -11 | D52: -86 | E52: -433 | F52: -426 | G52: -22
B53: Cash from Financing Activity | C53: -144 | D53: -345 | E53: 239 | F53: 262 | G53: -279
B54: Net Cash Flow | C54: 0 | D54: 0 | E54: 0 | F54: 0 | G54: 7
B55: Free Cash Flow | C55: 143 | D55: 345 | E55: -240 | F55: -262 | G55: 286

Sheet Sql Export
B2: Company_name | C2: Sector | D2: Fiscal_year | E2: Revenue | F2: EBITDA | G2: EBIT | H2: PAT | I2: Interest_Expense | J2: Total_assets | K2: Total_equity | L2: Total_debt | M2: Current_assets | N2: Current_liability | O2: CFO | P2: Debt_repayment | Q2: Market_cap | R2: Retained_Earnings | S2: Working_Capital
B3: Nitin Spinners Ltd. | C3: Textile | D3: 2022 | E3: 2404 | F3: 297 | G3: 210 | H3: 164 | I3: 38 | J3: 2218 | K3: 1029 | L3: 980 | M3: 866 | N3: 209 | O3: 194 | P3: 92 | Q3: 1232 | R3: 973 | S3: 657
B4: Nitin Spinners Ltd. | C4: Textile | D4: 2023 | E4: 2902 | F4: 377 | G4: 259 | H4: 132 | I4: 83 | J4: 2717 | K4: 1146 | L4: 1339 | M4: 1005 | N4: 231 | O4: 163 | P4: 107 | Q4: 1964 | R4: 1090 | S4: 774
B5: Nitin Spinners Ltd. | C5: Textile | D5: 2024 | E5: 3300 | F5: 471 | G5: 323 | H5: 175 | I5: 90 | J5: 2732 | K5: 1311 | L5: 1165 | M5: 1148 | N5: 256 | O5: 307 | P5: 174 | Q5: 2692 | R5: 1255 | S5: 892
B6: Sportking India Ltd. | C6: Textile | D6: 2022 | E6: 2204 | F6: 282 | G6: 216 | H6: 132 | I6: 26 | J6: 1575 | K6: 822 | L6: 474 | M6: 811 | N6: 332 | O6: 520 | P6: 317 | Q6: 953 | R6: 809 | S6: 479
B7: Sportking India Ltd. | C7: Textile | D7: 2023 | E7: 2376 | F7: 209 | G7: 159 | H7: 70 | I7: 63 | J7: 1963 | K7: 825 | L7: 874 | M7: 1177 | N7: 665 | O7: -236 | P7: 33 | Q7: 1043 | R7: 812 | S7: 512
B8: Sportking India Ltd. | C8: Textile | D8: 2024 | E8: 2524 | F8: 267 | G8: 204 | H8: 109 | I8: 54 | J8: 1775 | K8: 929 | L8: 585 | M8: 1011 | N8: 415 | O8: 415 | P8: 256 | Q8: 1323 | R8: 993 | S8: 610
B9: Sangam India Ltd | C9: Textile | D9: 2022 | E9: 2715 | F9: 302 | G9: 215 | H9: 135 | I9: 54 | J9: 2112 | K9: 887 | L9: 810 | M9: 1183 | N9: 899 | O9: 193 | P9: 81 | Q9: 1097 | R9: 842 | S9: 284
B10: Sangam India Ltd | C10: Textile | D10: 2023 | E10: 2648 | F10: 203 | G10: 121 | H10: 38 | I10: 68 | J10: 2656 | K10: 985 | L10: 1005 | M10: 1469 | N10: 1109 | O10: 179 | P10: 54 | Q10: 2135 | R10: 935 | S10: 360
B11: Sangam India Ltd | C11: Textile | D11: 2024 | E11: 2843 | F11: 225 | G11: 131 | H11: 27 | I11: 92 | J11: 2955 | K11: 1003 | L11: 1067 | M11: 1373 | N11: 1189 | O11: 433 | P11: 97 | Q11: 2084 | R11: 957 | S11: 226
B12: Pashupati Cotspin Ltd. | C12: Textile | D12: 2022 | E12: 443 | F12: 17 | G12: 16 | H12: 4 | I12: 10 | J12: 307 | K12: 111 | L12: 173 | M12: 135 | N12: 145 | O12: 22 | P12: 4.16 | Q12: 190 | R12: 96 | S12: -10
B13: Pashupati Cotspin Ltd. | C13: Textile | D13: 2023 | E13: 658 | F13: 30 | G13: 28 | H13: 8 | I13: 17 | J13: 310 | K13: 118 | L13: 151 | M13: 132 | N13: 146 | O13: 65 | P13: 22.69 | Q13: 156 | R13: 103 | S13: -14
B14: Pashupati Cotspin Ltd. | C14: Textile | D14: 2024 | E14: 637 | F14: 25 | G14: 30 | H14: 13 | I14: 13 | J14: 299 | K14: 155 | L14: 99 | M14: 121 | N14: 104 | O14: 52 | P14: 37.36 | Q14: 132 | R14: 139 | S14: 59
... B20: Deepak Spinners Ltd. | C20: Textile | D20: 2024 | E20: 524 | F20: 5 | G20: -10 | H20: -10 | I20: 4 | J20: 333 | K20: 225 | L20: 37 | M20: 157 | N20: 107.81 | O20: 27 | P20: 6.12 | Q20: 1590 | R20: 218 | S20: 42

Sheet Pbi Export
B2: Ratio | C2: Current Ratio | D2: Quick Ratio | E2: Cash Ratio | F2: Debt-to-Equity (D/E) | G2: Debt-to-Assets | H2: Interest Coverage Ratio | I2: Total Liabilities to Equity | J2: EBITDA Margin | K2: EBIT Margin | L2: PAT Margin (Net Margin) | M2: Return on Equity (ROE) | N2: Return on Assets (ROA) | O2: DSCR | P2: CFO to Total Debt | Q2: Debtor Days | R2: Inventory Days | S2: Asset Turnover | T2: Revenue Growth YoY | U2: PAT Growth YoY | V2: Z-Score | W2: Risk Zone | X2: EBITDA | Y2: EBIT | Z2: Profit Before Tax (PBT) | AA2: Profit After Tax (PAT) | AB2: Revenue from Operations
B3: FY2020 | C3: 4.0728477 | D3: 1.7218543 | E3: 0.0066225166 | F3: 1.7069272 | G3: 0.57304711 | H3: 2.6774194 | I3: 2.9751332 | J3: 0.15844636 | K3: 0.10234279 | L3: 0.042262639 | M3: 0.12175844 | N3: 0.040876565 | O3: 1.8028762 | P3: 0.16129032 | Q3: 37.355117 | R3: 79.885943 | S3: 0.96720334 | T3: N/A | U3: N/A | V3: 2.2020906 | W3: ⚠ Grey Zone | X3: 257 | Y3: 166 | Z3: 106 | AA3: 68.55 | AB3: 1622
B4: FY2021 | C4: 3.1230769 | D4: 1.5615385 | E4: 0.0038461538 | F4: 0.78538813 | G4: 0.37719298 | H4: 10.254545 | I4: 2.0821918 | J4: 0.24200743 | K4: 0.20966543 | L4: 0.12038662 | M4: 0.36968037 | N4: 0.17754386 | O4: 1.9821575 | P4: 0.62645349 | Q4: 32.700743 | R4: 55.089219 | S4: 1.4747807 | T4: 0.65844636 | U4: 3.724143 | V4: 4.008114 | W4: ✅ Safe Zone | X4: 651 | Y4: 564 | Z4: 506 | AA4: 323.84 | AB4: 2690
B5: FY2022 | C5: 4.1435407 | D5: 1.7894737 | E5: 0 | F5: 0.95238095 | G5: 0.44203879 | H5: 5.5263158 | I5: 2.1554908 | J5: 0.12354409 | K5: 0.087354409 | L5: 0.068402662 | M5: 0.15980564 | N5: 0.074172305 | O5: 2.2920204 | P5: 0.19795918 | Q5: 33.858153 | R5: 74.700499 | S5: 1.0843482 | T5: -0.1063197 | U5: -0.49221838 | V5: 2.7002556 | W5: ⚠ Grey Zone | X5: 297 | Y5: 210 | Z5: 175 | AA5: 164.44 | AB5: 2404
B6: FY2023 | C6: 4.3506494 | D6: 1.9090909 | E6: 0 | F6: 1.1684119 | G6: 0.49300442 | H6: 3.1204819 | I6: 2.3699825 | J6: 0.12991041 | K6: 0.089248794 | L6: 0.045389387 | M6: 0.11493892 | N6: 0.048497791 | O6: 1.9846283 | P6: 0.12173264 | Q6: 40.37388 | R6: 70.937285 | S6: 1.0684831 | T6: 0.20715474 | U6: -0.19897835 | V6: 2.7208763 | W6: ⚠ Grey Zone | X6: 377 | Y6: 259 | Z6: 178 | AA6: 131.72 | AB6: 2902
B7: FY2024 | C7: 4.484375 | D7: 2.1132812 | E7: 0.0390625 | F7: 0.88863463 | G7: 0.42642753 | H7: 3.5888889 | I7: 2.0839054 | J7: 0.14272727 | K7: 0.097878788 | L7: 0.053145455 | M7: 0.13377574 | N7: 0.064194729 | O7: 1.7815266 | P7: 0.26351931 | Q7: 47.560606 | R7: 67.137879 | S7: 1.2079063 | T7: 0.1371468 | U7: 0.33146067 | V7: 3.2241947 | W7: ✅ Safe Zone | X7: 471 | Y7: 323 | Z7: 237 | AA7: 175.38 | AB7: 3300
